Workbook
Name DB: #REF!

Sheet 帳票レイアウト Copy
B1: 検査梱包指示書
A3: 品目番号 | B3: J1JAPAB00419960 | C3: Ｌ寸 | D3: 1996 | E3: 名称 | F3: 採光ﾙｰﾊﾞｰﾊﾟﾈﾙB | I3: 上長 | J3: 係員
A5: 製造指図№ | B5: 000000000005329 | E5: 原料名 | F5: (J6VZ027)(J6AH0460)
A7: 発注明細№ | B7: 000000000772794 | E7: 色 名 | F7: WMC(ｸﾘｱ色)
E8: 製品Grp | F8: J1ZA
A9: 開始日 | B9: 45860 | E9: 入り数 | F9: 42
A10: 終了日 | B10: 45860 | E10: 梱包数 | F10: 1 | G10: 指示数量 | H10: 42
E11: 金 型 | F11: 4345
A12: *J1JAPAB00419960* | G12: 格納先 | H12: V3J03 | I12: 樹脂第3倉庫 (在庫)
A14: 指図書備考
A16: 工順 | B16: 製造場所 | C16: 製造場所名 | E16: 工程 | F16: 工程名 | I16: 作業時間
A18: 1 | B18: V3Z01 | C18: 黒部工業 | E18: V3P05 | F18: 切断
A19: 1 | B19: V3Z01 | C19: 黒部工業 | E19: V3P16 | F19: 検査・梱包
A25: 品目コード | C25: 品目名１ | F25: 在庫場所 | G25: 出庫数量 | I25: バッチ必要数
C26: 品目名２ | F26: 指図書備考
A28: J1JAPAA00420400 | C28: @採光ﾙｰﾊﾞｰﾊﾟﾈﾙB | F28: V3W04 | G28: 42 | I28: 1
A29: *J1JAPAA00420400* | C29: (J6VZ027)(J6AH0460)
A30: J6DK0011 | C30: 上-1 | F30: V3J03 | G30: 1.008 | I30: 0.024
A31: *J6DK0011*
A32: J6XX0017 | C32: (管理外)筋入ｸﾗﾌﾄ紙 | G32: 0.042 | I32: 0.001
A33: *J6XX0017* | C33: 600＊100
A38: 製品名 | E38: 備考、梱包方法等 | G38: 使用数 | H38: 加工内容 | J38: 不良内訳
A39: =_xlfn.XLOOKUP(B3,[1]VFDB2!A:A,[1]VFDB2!A:A) -> J1JAPAB00419960 | E39: {=IFERROR(IF(ISBLANK(INDEX(_xlfn._xlws.FILTER([1]加工記録２!$C$3:$C$992, [1]加工記録２!$T$3:$T$992=B5), 6)), "", INDEX(_xlfn._xlws.FILTER([1]加工記録２!$C$3:$C$992, [1]加工記録２!$T$3:$T$992=B5), 6)),"")} -> 上-1 | G39: {=IFERROR(IF(ISBLANK(INDEX(_xlfn._xlws.FILTER([1]加工記録２!$C$3:$C$992, [1]加工記録２!$T$3:$T$992=B5), 7)), " ", INDEX(_xlfn._xlws.FILTER([1]加工記録２!$C$3:$C$992, [1]加工記録２!$T$3:$T$992=B5), 7))," ")} -> 1 | H39: 入庫日 | I39: {=IFERROR(IF(ISBLANK(INDEX(_xlfn._xlws.FILTER([1]加工記録２!$O$3:$P$992, [1]加工記録２!$T$3:$T$992=B5), 1)), "", INDEX(_xlfn._xlws.FILTER([1]加工記録２!$O$3:$P$992, [1]加工記録２!$T$3:$T$992=B5), 1)),"")} -> 45860
H40: 入庫数 | I40: {=IFERROR(IF(ISBLANK(INDEX(_xlfn._xlws.FILTER([1]加工記録２!$O$3:$P$992, [1]加工記録２!$T$3:$T$992=B5), 2)), "", INDEX(_xlfn._xlws.FILTER([1]加工記録２!$O$3:$P$992, [1]加工記録２!$T$3:$T$992=B5), 2)),"")} -> 42
A41: 温度換算 | B41: =_xlfn.XLOOKUP(B3,[1]VFDB2!A:A,[1]VFDB2!J:J) -> 〇 | C41: 取数 | D41: =_xlfn.XLOOKUP(B3,[1]VFDB2!A:A,[1]VFDB2!P:P) -> 1 | E41: =_xlfn.XLOOKUP(B3,[1]VFDB2!A:A,[1]VFDB2!V:V) -> 0 | H41: 使用基材 | I41: {=IFERROR(IF(ISBLANK(INDEX(_xlfn._xlws.FILTER([1]加工記録２!$O$3:$P$992, [1]加工記録２!$T$3:$T$992=B5), 3)), "", INDEX(_xlfn._xlws.FILTER([1]加工記録２!$O$3:$P$992, [1]加工記録２!$T$3:$T$992=B5), 3)),"")} -> 42
H42: 基材不良 | I42: {=IFERROR(IF(ISBLANK(INDEX(_xlfn._xlws.FILTER([1]加工記録２!$O$3:$P$992, [1]加工記録２!$T$3:$T$992=B5), 4)), "", INDEX(_xlfn._xlws.FILTER([1]加工記録２!$O$3:$P$992, [1]加工記録２!$T$3:$T$992=B5), 4)),"")} -> 0
A43: L寸 | B43: =D3 -> 1996 | C43: +公差 | D43: =_xlfn.XLOOKUP(B3,[1]VFDB2!A:A,[1]VFDB2!L:L) -> +2 | E43: =_xlfn.XLOOKUP(B3,[1]VFDB2!A:A,[1]VFDB2!W:W) -> クラフト紙：1996型 | H43: 製品不良 | I43: {=IFERROR(IF(ISBLANK(INDEX(_xlfn._xlws.FILTER([1]加工記録２!$O$3:$P$992, [1]加工記録２!$T$3:$T$992=B5), 5)), "", INDEX(_xlfn._xlws.FILTER([1]加工記録２!$O$3:$P$992, [1]加工記録２!$T$3:$T$992=B5), 5)),"")} -> 0
H44: 端材使用 | I44: {=IFERROR(IF(ISBLANK(INDEX(_xlfn._xlws.FILTER([1]加工記録２!$O$3:$P$992, [1]加工記録２!$T$3:$T$992=B5), 6)), "", INDEX(_xlfn._xlws.FILTER([1]加工記録２!$O$3:$P$992, [1]加工記録２!$T$3:$T$992=B5), 6)),"")} -> 0
A45: 切断寸法 | B45: =_xlfn.XLOOKUP(B3,[1]VFDB2!A:A,[1]VFDB2!AC:AC) -> 換算表確認 | C45: -公差 | D45: =_xlfn.XLOOKUP(B3,[1]VFDB2!A:A,[1]VFDB2!K:K) -> 0 | E45: =_xlfn.XLOOKUP(B3,[1]VFDB2!A:A,[1]VFDB2!R:R) -> ラベル１枚 長手無 鉢巻２回 | H45: 切断者 | I45: {=IFERROR(IF(ISBLANK(INDEX(_xlfn._xlws.FILTER([1]加工記録２!$O$3:$P$992, [1]加工記録２!$T$3:$T$992=B5), 7)), "", INDEX(_xlfn._xlws.FILTER([1]加工記録２!$O$3:$P$992, [1]加工記録２!$T$3:$T$992=B5), 7)),"")} -> 富田・水野
H46: 検査者 | I46: {=IFERROR(IF(ISBLANK(INDEX(_xlfn._xlws.FILTER([1]加工記録２!$O$3:$P$992, [1]加工記録２!$T$3:$T$992=B5), 8)), "", INDEX(_xlfn._xlws.FILTER([1]加工記録２!$O$3:$P$992, [1]加工記録２!$T$3:$T$992=B5), 8)),"")} -> 上野 | J46: 0
A47: 作業日 | B47: 計測Lot | C47: 温度 | D47: 換算寸法 | E47: 計測値 | F47: 使用Lot | G47: 加工数 | H47: 基材換算 | I47: 加工Lot | J47: 箱数
A48: {=IFERROR(IF(ISBLANK(INDEX(_xlfn._xlws.FILTER([1]加工記録２!$D$3:$M$992, [1]加工記録２!$T$3:$T$992=B5), 1)), "", INDEX(_xlfn._xlws.FILTER([1]加工記録２!$D$3:$M$992, [1]加工記録２!$T$3:$T$992=B5), 1)),"")} -> 45667 | B48: 25A07-03 | F48: 25A07-03 | G48: 34 | H48: 34 | I48: 45860 | J48: 1
A49: {=IFERROR(IF(ISBLANK(INDEX(_xlfn._xlws.FILTER([1]加工記録２!$D$3:$M$992, [1]加工記録２!$T$3:$T$992=B5), 2)), "", INDEX(_xlfn._xlws.FILTER([1]加工記録２!$D$3:$M$992, [1]加工記録２!$T$3:$T$992=B5), 2)),"")} -> 45856 | B49: 25G16-01 | C49: 30 | D49: 1998.3 | E49: 1998.3 | F49: 25G16-01 | G49: 8 | H49: 8
A50: {=IFERROR(IF(ISBLANK(INDEX(_xlfn._xlws.FILTER([1]加工記録２!$D$3:$M$992, [1]加工記録２!$T$3:$T$992=B5), 3)), "", INDEX(_xlfn._xlws.FILTER([1]加工記録２!$D$3:$M$992, [1]加工記録２!$T$3:$T$992=B5), 3)),"")} -> 45856 | B50: 25G16-01 | C50: 30 | D50: 1998.3 | E50: 1998.3 | H50: 0
A51: {=IFERROR(IF(ISBLANK(INDEX(_xlfn._xlws.FILTER([1]加工記録２!$D$3:$M$992, [1]加工記録２!$T$3:$T$992=B5), 4)), "", INDEX(_xlfn._xlws.FILTER([1]加工記録２!$D$3:$M$992, [1]加工記録２!$T$3:$T$992=B5), 4)),"")} | H51: 0
A52: {=IFERROR(IF(ISBLANK(INDEX(_xlfn._xlws.FILTER([1]加工記録２!$D$3:$M$992, [1]加工記録２!$T$3:$T$992=B5), 5)), "", INDEX(_xlfn._xlws.FILTER([1]加工記録２!$D$3:$M$992, [1]加工記録２!$T$3:$T$992=B5), 5)),"")} | H52: 0
A53: {=IFERROR(IF(ISBLANK(INDEX(_xlfn._xlws.FILTER([1]加工記録２!$D$3:$M$992, [1]加工記録２!$T$3:$T$992=B5), 6)), "", INDEX(_xlfn._xlws.FILTER([1]加工記録２!$D$3:$M$992, [1]加工記録２!$T$3:$T$992=B5), 6)),"")} | H53: 0 | I53: 旧品加工 | J53: 34
A54: {=IFERROR(IF(ISBLANK(INDEX(_xlfn._xlws.FILTER([1]加工記録２!$D$3:$M$992, [1]加工記録２!$T$3:$T$992=B5), 7)), "", INDEX(_xlfn._xlws.FILTER([1]加工記録２!$D$3:$M$992, [1]加工記録２!$T$3:$T$992=B5), 7)),"")} | H54: 0 | I54: 持出端材
A55: {=IFERROR(IF(ISBLANK(INDEX(_xlfn._xlws.FILTER([1]加工記録２!$D$3:$M$992, [1]加工記録２!$T$3:$T$992=B5), 8)), "", INDEX(_xlfn._xlws.FILTER([1]加工記録２!$D$3:$M$992, [1]加工記録２!$T$3:$T$992=B5), 8)),"")} | H55: 0 | I55: α端材 | J55: 0
B58: 検査梱包指示書
...
