Workbook
Name DB: #REF!

Sheet 帳票レイアウト Copy
B1: 検査梱包指示書
A3: 品目番号 | B3: J1JAZZB10808880 | C3: Ｌ寸 | D3: 888 | E3: 名称 | F3: 8FL2813045010 | I3: 上長 | J3: 係員
A5: 製造指図№ | B5: 000000000012711 | E5: 原料名 | F5: (CASE 888MILK-W4)
A7: 発注明細№ | B7: 000000000837569 | E7: 色 名 | F7: J6VZ034
E8: 製品Grp | F8: J1ZB
A9: 開始日 | B9: 46092 | E9: 入り数 | F9: 100
A10: 終了日 | B10: 46092 | E10: 梱包数 | F10: 1 | G10: 指示数量 | H10: 100
E11: 金 型 | F11: 4350
A12: *J1JAZZB10808880* | G12: 格納先 | H12: V3J03 | I12: 樹脂第3倉庫 (在庫)
A14: 指図書備考
A16: 工順 | B16: 製造場所 | C16: 製造場所名 | E16: 工程 | F16: 工程名 | I16: 作業時間
A18: 1 | B18: V3Z01 | C18: 黒部工業 | E18: V3P05 | F18: 切断
A19: 1 | B19: V3Z01 | C19: 黒部工業 | E19: V3P16 | F19: 検査・梱包
A25: 品目コード | C25: 品目名１ | F25: 在庫場所 | G25: 出庫数量 | I25: バッチ必要数
C26: 品目名２ | F26: 指図書備考
A28: J1JAZZA10818200 | C28: @8FL28130 L1820 | F28: V3J04 | G28: 50 | I28: 0.5
A29: *J1JAZZA10818200*
A30: J6DW0089 | C30: LED-A888 898X275X166 | F30: V3Z01 | G30: 1 | I30: 0.01
A31: *J6DW0089* | C31: L888×W275×H166
A32: J6XX0044 | C32: (管理外)筋入ｸﾗﾌﾄ紙 | G32: 11 | I32: 0.11
A33: *J6XX0044* | C33: 400＊900
A34: J6XX0051 | C34: (管理外)LLDPE規格ｼｰﾄ0.02×950×100m | G34: 0.1 | I34: 0.001
A35: *J6XX0051* | C35: 0.02×950×100m
A38: 温度換算 | B38: L寸 | C38: 梱包箱 | E38: 使用数 | F38: 作業者 | G38: 加工Lot | H38: 箱数 | I38: 加工明細
A39: =_xlfn.XLOOKUP(B3,[1]VFDB2!$A:$A,[1]VFDB2!$J:$J) -> 〇 | B39: =D3 -> 888 | C39: =_xlfn.XLOOKUP(B3,[1]VFDB2!$A:$A,[1]VFDB2!$Z:$Z) -> LED-A888 | E39: {=IFERROR(INDEX(_xlfn._xlws.FILTER([2]加工記録２!C:C,[2]加工記録２!U:U=B5),9),"")} | F39: {=IFERROR("切断加工：" &_xlfn.TEXTJOIN(" / ",TRUE,INDEX(_xlfn._xlws.FILTER([2]加工記録２!M:M,[2]加工記録２!U:U=B5),9),INDEX(_xlfn._xlws.FILTER([2]加工記録２!N:N,[2]加工記録２!U:U=B5),9)),"")} | G39: {=IFERROR(IF(_xlfn.TAKE(_xlfn._xlws.FILTER([2]加工記録２!$M:$N,[2]加工記録２!$U:$U=B5),5)=0,"",_xlfn.TAKE(_xlfn._xlws.FILTER([2]加工記録２!$M:$N,[2]加工記録２!$U:$U=B5),5)),"")} | I39: 入庫日 | J39: {=IFERROR(INDEX(_xlfn._xlws.FILTER([2]加工記録２!P:P, [2]加工記録２!U:U=B5),_xlfn.SEQUENCE(6)),"")}
A40: +公差 | B40: 切断寸法 | F40: {=IFERROR("外観検査：" &_xlfn.TEXTJOIN(" / ",TRUE,INDEX(_xlfn._xlws.FILTER([2]加工記録２!M:M,[2]加工記録２!U:U=B5),10),INDEX(_xlfn._xlws.FILTER([2]加工記録２!N:N,[2]加工記録２!U:U=B5),10)),"")} | I40: 入庫数
A41: =_xlfn.XLOOKUP(B3,[1]VFDB2!$A:$A,[1]VFDB2!$L:$L) -> +0.5 | B41: =_xlfn.XLOOKUP(B3,[1]VFDB2!$A:$A,[1]VFDB2!$AC:$AC) -> 換算表確認 | C41: 梱包 方法 | D41: =_xlfn.XLOOKUP(B3,[1]VFDB2!$A:$A,[1]VFDB2!$W:$W) -> L=888用 クラフト紙 | I41: 使用基材数
A42: -公差 | B42: 取数 | D42: =_xlfn.XLOOKUP(B3,[1]VFDB2!$A:$A,[1]VFDB2!$R:$R) -> ラベル１枚 長手無 鉢巻１回 | I42: 製品不良
A43: =_xlfn.XLOOKUP(B3,[1]VFDB2!$A:$A,[1]VFDB2!$K:$K) -> －0.5 | B43: =_xlfn.XLOOKUP(B3,[1]VFDB2!$A:$A,[1]VFDB2!$P:$P) -> 2 | C43: 備考 | D43: =_xlfn.XLOOKUP(B3,[1]VFDB2!$A:$A,[1]VFDB2!$V:$V) -> 1箱目の梱包数 目視確認 以降、重量測定 | I43: 基材不良
A44: 作業日 | B44: {=IF(SUM(--(ISTEXT(B45:B55)*(B45:B55<>"")))=0,"計測Lot","計測Lot・加工数")} -> 計測Lot | C44: 温度 | D44: 換算 | E44: 計測値 | F44: {=IF(SUM(--(ISTEXT(B45:B55)*(B45:B55<>"")))=0,"記入不要","使用Lot")} -> 記入不要 | G44: 加工数 | H44: 基材換算 | I44: 端材使用
A45: {=IFERROR(INDEX(_xlfn._xlws.FILTER([2]加工記録２!$D:$D,[2]加工記録２!$U:$U=B5),_xlfn.SEQUENCE(11),0),"")} | B45: {=IFERROR(IF(INDEX(_xlfn._xlws.FILTER([2]加工記録２!$E:$E,[2]加工記録２!$U:$U=B5),_xlfn.SEQUENCE(11))="","",INDEX(_xlfn._xlws.FILTER([2]加工記録２!$E:$E,[2]加工記録２!$U:$U=B5),_xlfn.SEQUENCE(11)) & IF(INDEX(_xlfn._xlws.FILTER([2]加工記録２!$F:$F,[2]加工記録２!$U:$U=B5),_xlfn.SEQUENCE(11))="","", " × " & INDEX(_xlfn._xlws.FILTER([2]加工記録２!$F:$F,[2]加工記録２!$U:$U=B5),_xlfn.SEQUENCE(11)))),"")} | I45: 不良内訳
I46: キズ | J46: {=IFERROR(INDEX(_xlfn._xlws.FILTER([2]加工記録２!R:R, [2]加工記録２!U:U=B5),_xlfn.SEQUENCE(10)),"")}
I47: 凹み
I48: 異物
I49: 欠け
I50: メヤニ
I51: ベコツキ
I52: 汚損
I53: 形状異常
I54: その他
...
