Workbook
Name DB: #REF!

Sheet 帳票レイアウト Copy
B1: 検査梱包指示書
A3: 品目番号 | B3: ZZ001 | C3: Ｌ寸 | D3: 503 | E3: 名称 | F3: 461300-0050灯具カバーPC | I3: 上長 | J3: 係員
A5: 製造指図№ | B5: Z001 | E5: 原料名 | F5: -
A7: 発注明細№ | B7: 0000758073 | E7: 色 名 | F7: -
E8: 製品Grp | F8: -
A9: 開始日 | B9: - | E9: 入り数 | F9: 2
A10: 終了日 | B10: - | E10: 梱包数 | F10: 10 | G10: 指示数量 | H10: 10
E11: 金 型 | F11: -
A12: ZZ001 | G12: 格納先 | H12: V3J03 | I12: 樹脂第3倉庫 (在庫)
A14: 指図書備考
A16: 工順 | B16: 製造場所 | C16: 製造場所名 | E16: 工程 | F16: 工程名 | I16: 作業時間
A18: 1 | B18: V3Z01 | C18: 黒部工業 | E18: V3P05 | F18: 切断
A19: 1 | B19: V3Z01 | C19: 黒部工業 | E19: V3P13 | F19: 捺印
A20: 1 | B20: V3Z01 | C20: 黒部工業 | E20: V3P16 | F20: 検査・梱包
A25: 品目コード | C25: 品目名１ | F25: 在庫場所 | G25: 出庫数量 | I25: バッチ必要数
C26: 品目名２ | F26: 指図書備考
A38: 製品名 | E38: 梱包箱 | G38: 加工結果 | I38: 不良内訳
A39: {=_xlfn.XLOOKUP(A12,[1]!テーブル5[品目コード],[1]VFDB2!B2:B178,,2)} -> 灯具カバーPC L=503 | E39: =IFERROR(IF(OR(#REF!="", F9="", F9=0,#REF!/ F9=0), C30&" "&""&" 枚", C30&" "&#REF!/F9&" 枚"), C30&" "&""&" 枚") -> 枚 | G39: 入庫日 | H39: {=_xlfn._xlws.FILTER([1]加工記録２!Q:Q,B5=[1]加工記録２!$T:$T)} -> 0 | I39: キズ | J39: {=_xlfn._xlws.FILTER([1]加工記録２!O:O,B5=[1]加工記録２!$T:$T)} -> 45806
E40: 端材使用 有 ・ 無 | G40: 入庫数 | H40: 0 | I40: 凹み | J40: 10
A41: 温度換算 | B41: =_xlfn.XLOOKUP(A12,[1]!テーブル5[品目コード],[1]!テーブル5[温度換算],,2) -> 〇 | C41: 取数 | D41: =_xlfn.XLOOKUP(A12,[1]!テーブル5[品目コード],[1]!テーブル5[取数],,2) -> 1 | E41: 備考 | G41: 使用基材数 | H41: 0 | I41: 異物 | J41: 10
E42: =_xlfn.XLOOKUP(A12,[1]!テーブル5[品目コード],[1]!テーブル5[備考１],,2) -> 梱包箱:薄型1334 1/2 | G42: 基材不良 | H42: 0 | I42: 欠け | J42: 0
A43: L寸 | B43: =D3 -> 503 | C43: +公差 | D43: =_xlfn.XLOOKUP(A12,[1]!テーブル5[品目コード],[1]!テーブル5[上限公差],,2) -> +2 | E43: =_xlfn.XLOOKUP(A12,[1]!テーブル5[品目コード],[1]!テーブル5[備考２],,2) -> クラフト紙：1370型 1/2 | G43: 製品不良数 | H43: 0 | I43: メヤニ | J43: 0
E44: 梱包方法 | G44: 端材使用 | H44: 0 | I44: ベコツキ | J44: 0
A45: 切断寸法 | B45: =_xlfn.XLOOKUP(A12,[1]!テーブル5[品目コード],[1]!テーブル5[切断寸法],,2) -> 換算表確認 | C45: -公差 | D45: =_xlfn.XLOOKUP(A12,[1]!テーブル5[品目コード],[1]!テーブル5[下限公差],,2) -> -2 | E45: =_xlfn.XLOOKUP(A12,[1]!テーブル5[品目コード],[1]!テーブル5[梱包方法],,2) -> ラベル２枚 長手有 鉢巻無 | G45: 切断者 | H45: 0 | I45: その他 | J45: 水野
G46: 検査者 | H46: 0 | I46: 合計 | J46: -
A47: 作業日 | B47: 基材Lot | C47: 温度 | D47: 換算寸法 | E47: 計測値 | F47: 使用Lot | G47: B.加工数 | H47: C.基材換算 | I47: 加工Lot | J47: 箱数
A48: {=_xlfn._xlws.FILTER(IF([1]加工記録２!D:M="","",[1]加工記録２!D:M),B5=[1]加工記録２!$T:$T)} | F48: 25D11-01 | I48: 45806 | J48: 5 | P48: D,端材使用
A49: 45806 | B49: 25D11-01 | C49: 22 | E49: 503.7 | H49: 0
A50: 45806 | B50: 25D11-01 | C50: 22 | E50: 503.7
B58: 検査梱包指示書
A60: 品目番号 | B60: ZZ002 | C60: Ｌ寸 | D60: 669 | E60: 名称 | F60: 461300-0040灯具カバーPC | I60: 上長 | J60: 係員
A62: 製造指図№ | B62: Z002 | E62: 原料名 | F62: -
A64: 発注明細№ | B64: 0000758074 | E64: 色 名 | F64: -
E65: 製品Grp | F65: -
A66: 開始日 | B66: - | E66: 入り数 | F66: 2
A67: 終了日 | B67: - | E67: 梱包数 | F67: 10 | G67: 指示数量 | H67: 10
E68: 金 型 | F68: -
A69: ZZ002 | G69: 格納先 | H69: V3J03 | I69: 樹脂第3倉庫 (在庫)
A71: 指図書備考
A73: 工順 | B73: 製造場所 | C73: 製造場所名 | E73: 工程 | F73: 工程名 | I73: 作業時間
...
