Workbook
Name DB: #REF!

Sheet 帳票レイアウト Copy
B1: 検査梱包指示書
A3: 品目番号 | B3: J1EKACB22204150 | C3: Ｌ寸 | D3: 415 | E3: 名称 | F3: 001EGAW 415 | I3: 上長 | J3: 係員
A5: 製造指図№ | B5: 000000000003621 | E5: 原料名 | F5: (J1VB075) (J6VT048)
A7: 発注明細№ | B7: 000000000757219 | E7: 色 名 | F7: ﾎﾜｲﾄ
E8: 製品Grp | F8: J1EC
A9: 開始日 | B9: 45818 | E9: 入り数 | F9: 200
A10: 終了日 | B10: 45818 | E10: 梱包数 | F10: 7.5 | G10: 指示数量 | H10: 1500
E11: 金 型 | F11: 3714
A12: *J1EKACB22204150* | G12: 格納先 | H12: V3J03 | I12: 樹脂第3倉庫 (在庫)
A14: 指図書備考
A16: 工順 | B16: 製造場所 | C16: 製造場所名 | E16: 工程 | F16: 工程名 | I16: 作業時間
A18: 1 | B18: V3Z01 | C18: 黒部工業 | E18: V3P05 | F18: 切断
A19: 1 | B19: V3Z01 | C19: 黒部工業 | E19: V3P16 | F19: 検査・梱包
A25: 品目コード | C25: 品目名１ | F25: 在庫場所 | G25: 出庫数量 | I25: バッチ必要数
C26: 品目名２ | F26: 指図書備考
A28: J1EKACA22215000 | C28: @001EGAW 1500 | F28: V3J03 | G28: 499.5 | I28: 2.4975
A29: *J1EKACA22215000* | C29: (J1VB075) (J6VT048)
A30: J6DK0003 | C30: S-20 | F30: V3J03 | G30: 7.5 | I30: 0.0375
A31: *J6DK0003*
A38: 製品名 | E38: 梱包箱 | G38: A.不良内訳 | I38: 入庫日 | J38: 入庫数
A39: =F3 -> 001EGAW 415 | E39: S-20 8枚 | G39: キズ | H39: =_xlfn.XLOOKUP($B5, [1]加工記録２!$CD:$CD,[1]加工記録２!AH:AH) -> 0 | I39: =MAX(I51:I55) -> 45813 | J39: =_xlfn.XLOOKUP($B5, [1]加工記録２!$CD:$CD,[1]加工記録２!AD:AD,,0) -> 1500
E40: 端材使用 有 ・ 無 | G40: 凹み | H40: =_xlfn.XLOOKUP($B5, [1]加工記録２!$CD:$CD,[1]加工記録２!AI:AI,,0) -> 0
A41: 温度換算 | B41: =_xlfn.XLOOKUP(A12,[1]!テーブル5[品目コード],[1]!テーブル5[温度換算],,2) -> - | C41: 取数 | D41: =_xlfn.XLOOKUP(A12,[1]!テーブル5[品目コード],[1]!テーブル5[取数],,2) -> 3 | E41: 備考 | G41: 異物 | H41: =_xlfn.XLOOKUP($B5, [1]加工記録２!$CD:$CD,[1]加工記録２!AJ:AJ,,0) -> 0 | I41: 切断者 | J41: 検査者
E42: =_xlfn.XLOOKUP(A12,[1]!テーブル5[品目コード],[1]!テーブル5[備考１],,2) -> 0 | G42: 欠け | H42: =_xlfn.XLOOKUP($B5, [1]加工記録２!$CD:$CD,[1]加工記録２!AK:AK,,0) -> 0 | I42: =_xlfn.XLOOKUP($B5, [1]加工記録２!$CD:$CD,[1]加工記録２!CA:CA,,0) -> 水野 | J42: =_xlfn.XLOOKUP($B5, [1]加工記録２!$CD:$CD,[1]加工記録２!CB:CB,,0) -> -
A43: L寸 | B43: =D3 -> 415 | C43: +公差 | D43: =_xlfn.XLOOKUP(A12,[1]!テーブル5[品目コード],[1]!テーブル5[上限公差],,2) -> +0.5 | E43: =_xlfn.XLOOKUP(A12,[1]!テーブル5[品目コード],[1]!テーブル5[備考２],,2) -> ※使用基材、取数は依頼書にて確認 | G43: メヤニ | H43: =_xlfn.XLOOKUP($B5, [1]加工記録２!$CD:$CD,[1]加工記録２!AL:AL,,0) -> 0
E44: 梱包方法 | G44: ベコツキ | H44: =_xlfn.XLOOKUP($B5, [1]加工記録２!$CD:$CD,[1]加工記録２!AM:AM,,0) -> 0 | I44: E.製品不良数 | J44: F,基材不良
A45: 切断寸法 | B45: 415 | C45: -公差 | D45: =_xlfn.XLOOKUP(A12,[1]!テーブル5[品目コード],[1]!テーブル5[下限公差],,2) -> -0.5 | E45: =_xlfn.XLOOKUP(A12,[1]!テーブル5[品目コード],[1]!テーブル5[梱包方法],,2) -> ラベル２枚 長手有 鉢巻無 | G45: その他 | H45: =_xlfn.XLOOKUP($B5, [1]加工記録２!$CD:$CD,[1]加工記録２!AN:AN,,0) -> 2 | I45: =_xlfn.XLOOKUP($B5, [1]加工記録２!$CD:$CD,[1]加工記録２!AF:AF,,0) -> 2 | J45: =_xlfn.XLOOKUP($B5, [1]加工記録２!$CD:$CD,[1]加工記録２!AE:AE,,0) -> 1
G46: 合計 | H46: =SUM(H39:H45) -> 2
A47: 作業日 | B47: 基材Lot | C47: 温度 | D47: 換算寸法 | E47: 計測値 | F47: 備考、箱番号等 | G47: B.加工数 | H47: C.基材換算 | I47: D,端材使用 | J47: 使用基材数
A48: =IFERROR(_xlfn.XLOOKUP($B5&$J39,[1]加工記録２!B:B&[1]加工記録２!AD:AD,[1]加工記録２!BB:BB,,0),"/") -> / | B48: =_xlfn.XLOOKUP($B5,[1]加工記録２!$CD:$CD,[1]加工記録２!BJ:BJ,,0) | F48: ※前回加工による端数品 | G48: =IFERROR(SUM(H48*$D41),"") | H48: =_xlfn.XLOOKUP($B5,[1]加工記録２!$CD:$CD,[1]加工記録２!BR:BR,,0) | I48: =_xlfn.XLOOKUP($B5, [1]加工記録２!$CD:$CD,[1]加工記録２!AO:AO,,0) -> 866 | J48: =_xlfn.XLOOKUP($B5, [1]加工記録２!$CD:$CD,[1]加工記録２!AG:AG,,0) -> 212
A49: =IFERROR(_xlfn.XLOOKUP($B5&$J39,[1]加工記録２!$CD:$CD&[1]加工記録２!AD:AD,[1]加工記録２!BC:BC,,0),"/") -> 45813 | B49: =_xlfn.XLOOKUP($B5,[1]加工記録２!$CD:$CD,[1]加工記録２!BK:BK,,0) -> 25E22B | C49: =_xlfn.XLOOKUP($B5,[1]加工記録２!$CD:$CD,[1]加工記録２!P:P,,0) | D49: 415 | E49: =_xlfn.XLOOKUP($B5, [1]加工記録２!$CD:$CD,[1]加工記録２!W:W,,0) -> 415.12 | F49: 端材品 | H49: =_xlfn.XLOOKUP($B5,[1]加工記録２!$CD:$CD,[1]加工記録２!BS:BS,,0) -> 0
A50: =IFERROR(_xlfn.XLOOKUP($B5&$J39,[1]加工記録２!$CD:$CD&[1]加工記録２!AD:AD,[1]加工記録２!BD:BD,,0),"/") -> 45813 | B50: =_xlfn.XLOOKUP($B5,[1]加工記録２!CD:CD,[1]加工記録２!BL:BL,,0) -> 25E23C | C50: =_xlfn.XLOOKUP($B5,[1]加工記録２!$CD:$CD,[1]加工記録２!Q:Q,,0) | E50: =_xlfn.XLOOKUP($B5, [1]加工記録２!$CD:$CD,[1]加工記録２!X:X,,0) | F50: 端材品 | H50: =_xlfn.XLOOKUP($B5,[1]加工記録２!$CD:$CD,[1]加工記録２!BT:BT,,0) -> 0 | I50: 加工Lot | J50: 箱数
A51: =IFERROR(_xlfn.XLOOKUP($B5&$J39,[1]加工記録２!$CD:$CD&[1]加工記録２!AD:AD,[1]加工記録２!BE:BE,,0),"/") -> 45813 | B51: =_xlfn.XLOOKUP($B5,[1]加工記録２!$CD:$CD,[1]加工記録２!BM:BM,,0) -> 25E24A | C51: =_xlfn.XLOOKUP($B5,[1]加工記録２!$CD:$CD,[1]加工記録２!R:R,,0) | E51: =_xlfn.XLOOKUP($B5, [1]加工記録２!$CD:$CD,[1]加工記録２!Y:Y,,0) -> 415.12 | F51: 端材品 | H51: =_xlfn.XLOOKUP($B5,[1]加工記録２!$CD:$CD,[1]加工記録２!BU:BU,,0) -> 0 | I51: =_xlfn.LET(_xlpm.val,_xlfn.XLOOKUP($B5,[1]加工記録２!$CD:$CD,[1]加工記録２!AQ:AQ,""),IF(OR(_xlpm.val="",_xlpm.val=0),"",_xlpm.val)) -> 45813 | J51: =_xlfn.LET(_xlpm.val,_xlfn.XLOOKUP($B5,[1]加工記録２!$CD:$CD,[1]加工記録２!AR:AR,""),IF(OR(_xlpm.val="",_xlpm.val=0),"",_xlpm.val)) -> 8
A52: =IFERROR(_xlfn.XLOOKUP($B5&$J39,[1]加工記録２!$CD:$CD&[1]加工記録２!AD:AD,[1]加工記録２!BF:BF,,0),"/") -> 45813 | B52: =_xlfn.XLOOKUP($B5,[1]加工記録２!$CD:$CD,[1]加工記録２!BN:BN,,0) -> 25E23B | E52: =_xlfn.XLOOKUP($B5, [1]加工記録２!$CD:$CD,[1]加工記録２!Z:Z,,0) | G52: =IFERROR(SUM(H52*$D41),"") -> 600 | H52: =_xlfn.XLOOKUP($B5,[1]加工記録２!$CD:$CD,[1]加工記録２!BV:BV,,0) -> 200 | I52: =_xlfn.LET(_xlpm.val,_xlfn.XLOOKUP($B5,[1]加工記録２!$CD:$CD,[1]加工記録２!AS:AS,""),IF(OR(_xlpm.val="",_xlpm.val=0),"",_xlpm.val)) | J52: =_xlfn.LET(_xlpm.val,_xlfn.XLOOKUP($B5,[1]加工記録２!$CD:$CD,[1]加工記録２!AT:AT,""),IF(OR(_xlpm.val="",_xlpm.val=0),"",_xlpm.val))
A53: =IFERROR(_xlfn.XLOOKUP($B5&$J39,[1]加工記録２!$CD:$CD&[1]加工記録２!AD:AD,[1]加工記録２!BG:BG,,0),"/") -> 45813 | B53: =_xlfn.XLOOKUP($B5,[1]加工記録２!$CD:$CD,[1]加工記録２!BO:BO,,0) -> 25A15B | E53: =_xlfn.XLOOKUP($B5, [1]加工記録２!$CD:$CD,[1]加工記録２!AA:AA,,0) -> 415.21 | G53: =IFERROR(SUM(H53*$D41),"") -> 36 | H53: =_xlfn.XLOOKUP($B5,[1]加工記録２!$CD:$CD,[1]加工記録２!BW:BW,,0) -> 12 | I53: =_xlfn.LET(_xlpm.val,_xlfn.XLOOKUP($B5,[1]加工記録２!$CD:$CD,[1]加工記録２!AU:AU,""),IF(OR(_xlpm.val="",_xlpm.val=0),"",_xlpm.val)) | J53: =_xlfn.LET(_xlpm.val,_xlfn.XLOOKUP($B5,[1]加工記録２!$CD:$CD,[1]加工記録２!AV:AV,""),IF(OR(_xlpm.val="",_xlpm.val=0),"",_xlpm.val))
A54: =IFERROR(_xlfn.XLOOKUP($B5&$J39,[1]加工記録２!$CD:$CD&[1]加工記録２!AD:AD,[1]加工記録２!BH:BH,,0),"/") | B54: =_xlfn.XLOOKUP($B5,[1]加工記録２!$CD:$CD,[1]加工記録２!BP:BP,,0) | C54: =_xlfn.XLOOKUP($B5,[1]加工記録２!$CD:$CD,[1]加工記録２!U:U,,0) | E54: =_xlfn.XLOOKUP($B5, [1]加工記録２!$CD:$CD,[1]加工記録２!AB:AB,,0) | G54: =IFERROR(SUM(H54*$D41),"") | H54: =_xlfn.XLOOKUP($B5,[1]加工記録２!$CD:$CD,[1]加工記録２!BX:BX,,0) | I54: =_xlfn.LET(_xlpm.val,_xlfn.XLOOKUP($B5,[1]加工記録２!$CD:$CD,[1]加工記録２!AW:AW,""),IF(OR(_xlpm.val="",_xlpm.val=0),"",_xlpm.val)) | J54: =_xlfn.LET(_xlpm.val,_xlfn.XLOOKUP($B5,[1]加工記録２!$CD:$CD,[1]加工記録２!AX:AX,""),IF(OR(_xlpm.val="",_xlpm.val=0),"",_xlpm.val))
A55: =IFERROR(_xlfn.XLOOKUP($B5&$J39,[1]加工記録２!$CD:$CD&[1]加工記録２!AD:AD,[1]加工記録２!BI:BI,,0),"/") | B55: =_xlfn.XLOOKUP($B5,[1]加工記録２!$CD:$CD,[1]加工記録２!BQ:BQ,,0) | C55: =_xlfn.XLOOKUP($B5,[1]加工記録２!$CD:$CD,[1]加工記録２!V:V,,0) | E55: =_xlfn.XLOOKUP($B5, [1]加工記録２!$CD:$CD,[1]加工記録２!AC:AC,,0) | G55: =IFERROR(SUM(H55*$D41),"") | H55: =_xlfn.XLOOKUP($B5,[1]加工記録２!$CD:$CD,[1]加工記録２!BY:BY,,0) | I55: =_xlfn.LET(_xlpm.val,_xlfn.XLOOKUP($B5,[1]加工記録２!$CD:$CD,[1]加工記録２!AY:AY,""),IF(OR(_xlpm.val="",_xlpm.val=0),"",_xlpm.val)) | J55: =_xlfn.LET(_xlpm.val,_xlfn.XLOOKUP($B5,[1]加工記録２!$CD:$CD,[1]加工記録２!AZ:AZ,""),IF(OR(_xlpm.val="",_xlpm.val=0),"",_xlpm.val))
B58: 検査梱包指示書
A60: 品目番号 | B60: J1EKACB22205080 | C60: Ｌ寸 | D60: 508 | E60: 名称 | F60: 001EGAW 508 | I60: 上長 | J60: 係員
A62: 製造指図№ | B62: 000000000003622 | E62: 原料名 | F62: (J1VB075) (J6VT048)
...
