Workbook
Name DB: #REF!

Sheet 帳票レイアウト Copy
B1: 検査梱包指示書
A3: 品目番号 | B3: J1ZAFJB00102218 | C3: Ｌ寸 | D3: 221 | E3: 名称 | F3: 463301-2200灯具ｶﾊﾞｰPC | I3: 上長 | J3: 係員
A5: 製造指図№ | B5: 000000000003336 | E5: 原料名 | F5: J6VZ041
A7: 発注明細№ | B7: 000000000754609 | E7: 色 名 | F7: 拡散
E8: 製品Grp | F8: J1ZA
A9: 開始日 | B9: 45817 | E9: 入り数 | F9: 2
A10: 終了日 | B10: 45817 | E10: 梱包数 | F10: 10 | G10: 指示数量 | H10: 20
E11: 金 型 | F11: 4317
A12: *J1ZAFJB00102218* | G12: 格納先 | H12: V3J03 | I12: 樹脂第3倉庫 (在庫)
A14: 指図書備考
A16: 工順 | B16: 製造場所 | C16: 製造場所名 | E16: 工程 | F16: 工程名 | I16: 作業時間
A18: 1 | B18: V3Z01 | C18: 黒部工業 | E18: V3P05 | F18: 切断
A19: 1 | B19: V3Z01 | C19: 黒部工業 | E19: V3P13 | F19: 捺印
A20: 1 | B20: V3Z01 | C20: 黒部工業 | E20: V3P16 | F20: 検査・梱包
A25: 品目コード | C25: 品目名１ | F25: 在庫場所 | G25: 出庫数量 | I25: バッチ必要数
C26: 品目名２ | F26: 指図書備考
A28: J1ZAFJA00205470 | C28: @463301-2140灯具ｶﾊﾞｰPCIN | F28: V3J04 | G28: 4 | I28: 2
A29: *J1ZAFJA00205470* | C29: J6VZ041
A30: J6DK0027 | C30: H型ｼﾞｮｲﾅ- | F30: V3J03 | G30: 10 | I30: 5
A31: *J6DK0027*
A38: 製品名 | E38: 梱包箱 | G38: A.不良内訳 | I38: 入庫日 | J38: 入庫数
A39: =F3 -> 463301-2200灯具ｶﾊﾞｰPC | E39: =IFERROR(IF(OR(J39="", F9="", F9=0, J39/F9=0), C30&" "&""&" 枚", C30&" "&J39/F9&" 枚"), C30&" "&""&" 枚") -> H型ｼﾞｮｲﾅ- 10 枚 | G39: キズ | H39: =_xlfn.XLOOKUP(RIGHT($B7,8), [1]加工記録２!$B:$B,[1]加工記録２!AH:AH) -> 0 | I39: =MAX(I51:I55) -> 45798 | J39: =_xlfn.XLOOKUP(RIGHT($B7,8), [1]加工記録２!$B:$B,[1]加工記録２!AD:AD,,0) -> 20
E40: 端材使用 有 | G40: 凹み | H40: =_xlfn.XLOOKUP(RIGHT($B7,8), [1]加工記録２!$B:$B,[1]加工記録２!AI:AI,,0) -> 4
A41: 温度換算 | B41: =_xlfn.XLOOKUP(A12,[1]!テーブル5[品目コード],[1]!テーブル5[温度換算],,2) -> 〇 | C41: 取数 | D41: =_xlfn.XLOOKUP(A12,[1]!テーブル5[品目コード],[1]!テーブル5[取数],,2) -> 2 | E41: 備考 | G41: 異物 | H41: =_xlfn.XLOOKUP(RIGHT($B7,8), [1]加工記録２!$B:$B,[1]加工記録２!AJ:AJ,,0) -> 0 | I41: 切断者 | J41: 検査者
E42: =_xlfn.XLOOKUP(A12,[1]!テーブル5[品目コード],[1]!テーブル5[備考１],,2) -> 梱包箱:薄型1334 1/4 | G42: 欠け | H42: =_xlfn.XLOOKUP(RIGHT($B7,8), [1]加工記録２!$B:$B,[1]加工記録２!AK:AK,,0) -> 0 | I42: =_xlfn.XLOOKUP(RIGHT($B7,8), [1]加工記録２!$B:$B,[1]加工記録２!CA:CA,,0) -> 水野 | J42: =_xlfn.XLOOKUP(RIGHT($B7,8), [1]加工記録２!$B:$B,[1]加工記録２!CB:CB,,0) -> 高森
A43: L寸 | B43: =D3 -> 221 | C43: +公差 | D43: =_xlfn.XLOOKUP(A12,[1]!テーブル5[品目コード],[1]!テーブル5[上限公差],,2) -> +2 | E43: =_xlfn.XLOOKUP(A12,[1]!テーブル5[品目コード],[1]!テーブル5[備考２],,2) -> クラフト紙：1996型 1/8 | G43: メヤニ | H43: =_xlfn.XLOOKUP(RIGHT($B7,8), [1]加工記録２!$B:$B,[1]加工記録２!AL:AL,,0) -> 0
E44: 梱包方法 | G44: ベコツキ | H44: =_xlfn.XLOOKUP(RIGHT($B7,8), [1]加工記録２!$B:$B,[1]加工記録２!AM:AM,,0) -> 0 | I44: E.製品不良数 | J44: F,基材不良
A45: 切断寸法 | B45: =_xlfn.XLOOKUP(A12,[1]!テーブル5[品目コード],[1]!テーブル5[切断寸法],,2) -> 換算表確認 | C45: -公差 | D45: =_xlfn.XLOOKUP(A12,[1]!テーブル5[品目コード],[1]!テーブル5[下限公差],,2) -> -2 | E45: =_xlfn.XLOOKUP(A12,[1]!テーブル5[品目コード],[1]!テーブル5[梱包方法],,2) -> ラベル２枚 長手有 鉢巻無 | G45: その他 | H45: =_xlfn.XLOOKUP(RIGHT($B7,8), [1]加工記録２!$B:$B,[1]加工記録２!AN:AN,,0) -> 0 | I45: =_xlfn.XLOOKUP(RIGHT($B7,8), [1]加工記録２!$B:$B,[1]加工記録２!AF:AF,,0) -> 4 | J45: =_xlfn.XLOOKUP(RIGHT($B7,8), [1]加工記録２!$B:$B,[1]加工記録２!AE:AE,,0) -> 2
G46: 合計 | H46: =SUM(H39:H45) -> 4
A47: 作業日 | B47: 基材Lot | C47: 温度 | D47: 換算寸法 | E47: 計測値 | F47: 備考、箱番号等 | G47: B.加工数 | H47: C.基材換算 | I47: D,端材使用 | J47: 使用基材数
A48: =IFERROR(_xlfn.XLOOKUP(RIGHT($B7,8)&$J39,[1]加工記録２!B:B&[1]加工記録２!AD:AD,[1]加工記録２!BB:BB,,0),"/") | B48: =_xlfn.XLOOKUP(RIGHT($B7,8),[1]加工記録２!$B:$B,[1]加工記録２!BJ:BJ,,0) | F48: ※前回加工による端数品 | G48: =IFERROR(SUM(H48*$D41),"") | H48: =_xlfn.XLOOKUP(RIGHT($B7,8),[1]加工記録２!$B:$B,[1]加工記録２!BR:BR,,0) | I48: =_xlfn.XLOOKUP(RIGHT($B7,8), [1]加工記録２!$B:$B,[1]加工記録２!AO:AO,,0) -> 0 | J48: =_xlfn.XLOOKUP(RIGHT($B7,8), [1]加工記録２!$B:$B,[1]加工記録２!AG:AG,,0) -> 12
A49: =IFERROR(_xlfn.XLOOKUP(RIGHT($B7,8)&$J39,[1]加工記録２!B:B&[1]加工記録２!AD:AD,[1]加工記録２!BC:BC,,0),"/") -> 45798 | B49: =_xlfn.XLOOKUP(RIGHT($B7,8),[1]加工記録２!$B:$B,[1]加工記録２!BK:BK,,0) -> 25E16-01 | C49: =_xlfn.XLOOKUP(RIGHT($B7,8),[1]加工記録２!$B:$B,[1]加工記録２!P:P,,0) -> 26 | D49: =IFERROR(_xlfn.XLOOKUP(IF(_xlfn.XLOOKUP(RIGHT($B7,8),[1]加工記録２!$B:$B,[1]加工記録２!C:C,,0)="","",_xlfn.XLOOKUP(RIGHT($B7,8),[1]加工記録２!$B:$B,[1]加工記録２!C:C,,0))&C49,[1]温度換算!A:A,[1]温度換算!C:C),"") -> 222.3 | E49: =_xlfn.XLOOKUP(RIGHT($B7,8), [1]加工記録２!$B:$B,[1]加工記録２!W:W,,0) -> 221.85 | G49: =IFERROR(SUM(H49*$D41),"") -> 24 | H49: =_xlfn.XLOOKUP(RIGHT($B7,8),[1]加工記録２!$B:$B,[1]加工記録２!BS:BS,,0) -> 12
A50: =IFERROR(_xlfn.XLOOKUP(RIGHT($B7,8)&$J39,[1]加工記録２!B:B&[1]加工記録２!AD:AD,[1]加工記録２!BD:BD,,0),"/") -> 45798 | B50: =_xlfn.XLOOKUP(RIGHT($B7,8),[1]加工記録２!B:B,[1]加工記録２!BL:BL,,0) -> 25E16-01 | C50: =_xlfn.XLOOKUP(RIGHT($B7,8),[1]加工記録２!$B:$B,[1]加工記録２!Q:Q,,0) -> 26 | D50: =IFERROR(_xlfn.XLOOKUP(IF(_xlfn.XLOOKUP(RIGHT($B7,8),[1]加工記録２!$B:$B,[1]加工記録２!C:C,,0)="","",_xlfn.XLOOKUP(RIGHT($B7,8),[1]加工記録２!$B:$B,[1]加工記録２!C:C,,0))&C50,[1]温度換算!A:A,[1]温度換算!C:C),"") -> 222.3 | E50: =_xlfn.XLOOKUP(RIGHT($B7,8), [1]加工記録２!$B:$B,[1]加工記録２!X:X,,0) -> 221.83 | G50: =IFERROR(SUM(H50*$D41),"") | H50: =_xlfn.XLOOKUP(RIGHT($B7,8),[1]加工記録２!$B:$B,[1]加工記録２!BT:BT,,0) | I50: 加工Lot | J50: 箱数
A51: =IFERROR(_xlfn.XLOOKUP(RIGHT($B7,8)&$J39,[1]加工記録２!B:B&[1]加工記録２!AD:AD,[1]加工記録２!BE:BE,,0),"/") | B51: =_xlfn.XLOOKUP(RIGHT($B7,8),[1]加工記録２!B:B,[1]加工記録２!BM:BM,,0) | C51: =_xlfn.XLOOKUP(RIGHT($B7,8),[1]加工記録２!$B:$B,[1]加工記録２!R:R,,0) | D51: =IFERROR(_xlfn.XLOOKUP(IF(_xlfn.XLOOKUP(RIGHT($B7,8),[1]加工記録２!$B:$B,[1]加工記録２!C:C,,0)="","",_xlfn.XLOOKUP(RIGHT($B7,8),[1]加工記録２!$B:$B,[1]加工記録２!C:C,,0))&C51,[1]温度換算!A:A,[1]温度換算!C:C),"") | E51: =_xlfn.XLOOKUP(RIGHT($B7,8), [1]加工記録２!$B:$B,[1]加工記録２!Y:Y,,0) | G51: =IFERROR(SUM(H51*$D41),"") | H51: =_xlfn.XLOOKUP(RIGHT($B7,8),[1]加工記録２!$B:$B,[1]加工記録２!BU:BU,,0) | I51: =_xlfn.LET(_xlpm.val,_xlfn.XLOOKUP(RIGHT($B7,8),[1]加工記録２!$B:$B,[1]加工記録２!AQ:AQ,""),IF(OR(_xlpm.val="",_xlpm.val=0),"",_xlpm.val)) -> 45798 | J51: =_xlfn.LET(_xlpm.val,_xlfn.XLOOKUP(RIGHT($B7,8),[1]加工記録２!$B:$B,[1]加工記録２!AR:AR,""),IF(OR(_xlpm.val="",_xlpm.val=0),"",_xlpm.val)) -> 10
A52: =IFERROR(_xlfn.XLOOKUP(RIGHT($B7,8)&$J39,[1]加工記録２!B:B&[1]加工記録２!AD:AD,[1]加工記録２!BF:BF,,0),"/") | B52: =_xlfn.XLOOKUP(RIGHT($B7,8),[1]加工記録２!B:B,[1]加工記録２!BN:BN,,0) | C52: =_xlfn.XLOOKUP(RIGHT($B7,8),[1]加工記録２!$B:$B,[1]加工記録２!S:S,,0) | D52: =IFERROR(_xlfn.XLOOKUP(IF(_xlfn.XLOOKUP(RIGHT($B7,8),[1]加工記録２!$B:$B,[1]加工記録２!C:C,,0)="","",_xlfn.XLOOKUP(RIGHT($B7,8),[1]加工記録２!$B:$B,[1]加工記録２!C:C,,0))&C52,[1]温度換算!A:A,[1]温度換算!C:C),"") | E52: =_xlfn.XLOOKUP(RIGHT($B7,8), [1]加工記録２!$B:$B,[1]加工記録２!Z:Z,,0) | G52: =IFERROR(SUM(H52*$D41),"") | H52: =_xlfn.XLOOKUP(RIGHT($B7,8),[1]加工記録２!$B:$B,[1]加工記録２!BV:BV,,0) | I52: =_xlfn.LET(_xlpm.val,_xlfn.XLOOKUP(RIGHT($B7,8),[1]加工記録２!$B:$B,[1]加工記録２!AS:AS,""),IF(OR(_xlpm.val="",_xlpm.val=0),"",_xlpm.val)) | J52: =_xlfn.LET(_xlpm.val,_xlfn.XLOOKUP(RIGHT($B7,8),[1]加工記録２!$B:$B,[1]加工記録２!AT:AT,""),IF(OR(_xlpm.val="",_xlpm.val=0),"",_xlpm.val))
A53: =IFERROR(_xlfn.XLOOKUP(RIGHT($B7,8)&$J39,[1]加工記録２!B:B&[1]加工記録２!AD:AD,[1]加工記録２!BG:BG,,0),"/") | B53: =_xlfn.XLOOKUP(RIGHT($B7,8),[1]加工記録２!B:B,[1]加工記録２!BO:BO,,0) | C53: =_xlfn.XLOOKUP(RIGHT($B7,8),[1]加工記録２!$B:$B,[1]加工記録２!T:T,,0) | D53: =IFERROR(_xlfn.XLOOKUP(IF(_xlfn.XLOOKUP(RIGHT($B7,8),[1]加工記録２!$B:$B,[1]加工記録２!C:C,,0)="","",_xlfn.XLOOKUP(RIGHT($B7,8),[1]加工記録２!$B:$B,[1]加工記録２!C:C,,0))&C53,[1]温度換算!A:A,[1]温度換算!C:C),"") | E53: =_xlfn.XLOOKUP(RIGHT($B7,8), [1]加工記録２!$B:$B,[1]加工記録２!AA:AA,,0) | G53: =IFERROR(SUM(H53*$D41),"") | H53: =_xlfn.XLOOKUP(RIGHT($B7,8),[1]加工記録２!$B:$B,[1]加工記録２!BW:BW,,0) | I53: =_xlfn.LET(_xlpm.val,_xlfn.XLOOKUP(RIGHT($B7,8),[1]加工記録２!$B:$B,[1]加工記録２!AU:AU,""),IF(OR(_xlpm.val="",_xlpm.val=0),"",_xlpm.val)) | J53: =_xlfn.LET(_xlpm.val,_xlfn.XLOOKUP(RIGHT($B7,8),[1]加工記録２!$B:$B,[1]加工記録２!AV:AV,""),IF(OR(_xlpm.val="",_xlpm.val=0),"",_xlpm.val))
A54: =IFERROR(_xlfn.XLOOKUP(RIGHT($B7,8)&$J39,[1]加工記録２!B:B&[1]加工記録２!AD:AD,[1]加工記録２!BH:BH,,0),"/") | B54: =_xlfn.XLOOKUP(RIGHT($B7,8),[1]加工記録２!B:B,[1]加工記録２!BP:BP,,0) | C54: =_xlfn.XLOOKUP(RIGHT($B7,8),[1]加工記録２!$B:$B,[1]加工記録２!U:U,,0) | D54: =IFERROR(_xlfn.XLOOKUP(IF(_xlfn.XLOOKUP(RIGHT($B7,8),[1]加工記録２!$B:$B,[1]加工記録２!C:C,,0)="","",_xlfn.XLOOKUP(RIGHT($B7,8),[1]加工記録２!$B:$B,[1]加工記録２!C:C,,0))&C54,[1]温度換算!A:A,[1]温度換算!C:C),"") | E54: =_xlfn.XLOOKUP(RIGHT($B7,8), [1]加工記録２!$B:$B,[1]加工記録２!AB:AB,,0) | G54: =IFERROR(SUM(H54*$D41),"") | H54: =_xlfn.XLOOKUP(RIGHT($B7,8),[1]加工記録２!$B:$B,[1]加工記録２!BX:BX,,0) | I54: =_xlfn.LET(_xlpm.val,_xlfn.XLOOKUP(RIGHT($B7,8),[1]加工記録２!$B:$B,[1]加工記録２!AW:AW,""),IF(OR(_xlpm.val="",_xlpm.val=0),"",_xlpm.val)) | J54: =_xlfn.LET(_xlpm.val,_xlfn.XLOOKUP(RIGHT($B7,8),[1]加工記録２!$B:$B,[1]加工記録２!AX:AX,""),IF(OR(_xlpm.val="",_xlpm.val=0),"",_xlpm.val))
A55: =IFERROR(_xlfn.XLOOKUP(RIGHT($B7,8)&$J39,[1]加工記録２!B:B&[1]加工記録２!AD:AD,[1]加工記録２!BI:BI,,0),"/") | B55: =_xlfn.XLOOKUP(RIGHT($B7,8),[1]加工記録２!B:B,[1]加工記録２!BQ:BQ,,0) | C55: =_xlfn.XLOOKUP(RIGHT($B7,8),[1]加工記録２!$B:$B,[1]加工記録２!V:V,,0) | D55: =IFERROR(_xlfn.XLOOKUP(IF(_xlfn.XLOOKUP(RIGHT($B7,8),[1]加工記録２!$B:$B,[1]加工記録２!C:C,,0)="","",_xlfn.XLOOKUP(RIGHT($B7,8),[1]加工記録２!$B:$B,[1]加工記録２!C:C,,0))&C55,[1]温度換算!A:A,[1]温度換算!C:C),"") | E55: =_xlfn.XLOOKUP(RIGHT($B7,8), [1]加工記録２!$B:$B,[1]加工記録２!AC:AC,,0) | G55: =IFERROR(SUM(H55*$D41),"") | H55: =_xlfn.XLOOKUP(RIGHT($B7,8),[1]加工記録２!$B:$B,[1]加工記録２!BY:BY,,0) | I55: =_xlfn.LET(_xlpm.val,_xlfn.XLOOKUP(RIGHT($B7,8),[1]加工記録２!$B:$B,[1]加工記録２!AY:AY,""),IF(OR(_xlpm.val="",_xlpm.val=0),"",_xlpm.val)) | J55: =_xlfn.LET(_xlpm.val,_xlfn.XLOOKUP(RIGHT($B7,8),[1]加工記録２!$B:$B,[1]加工記録２!AZ:AZ,""),IF(OR(_xlpm.val="",_xlpm.val=0),"",_xlpm.val))
B58: 検査梱包指示書
A60: 品目番号 | B60: J1ZAFJB00205470 | C60: Ｌ寸 | D60: 547 | E60: 名称 | F60: 463301-2140灯具ｶﾊﾞｰPC IN | I60: 上長 | J60: 係員
...
