Workbook
Name DB: #REF!

Sheet 帳票レイアウト Copy
B1: 検査梱包指示書
A3: 品目番号 | B3: J1JAZZB10802970 | C3: Ｌ寸 | D3: 297 | E3: 名称 | F3: 8FL2813044810 | I3: 上長 | J3: 係員
A5: 製造指図№ | B5: 000000000004069 | E5: 原料名 | F5: (CASE 297MILK-W4)
A7: 発注明細№ | B7: 000000000761437 | E7: 色 名 | F7: J6VZ034
E8: 製品Grp | F8: J1ZB
A9: 開始日 | B9: 45834 | E9: 入り数 | F9: 100
A10: 終了日 | B10: 45834 | E10: 梱包数 | F10: 3 | G10: 指示数量 | H10: 300
E11: 金 型 | F11: 4350
A12: *J1JAZZB10802970* | G12: 格納先 | H12: V3J04 | I12: 樹脂第4倉庫 (在庫)
A14: 指図書備考
A16: 工順 | B16: 製造場所 | C16: 製造場所名 | E16: 工程 | F16: 工程名 | I16: 作業時間
A18: 1 | B18: V3Z01 | C18: 黒部工業 | E18: V3P05 | F18: 切断
A19: 1 | B19: V3Z01 | C19: 黒部工業 | E19: V3P16 | F19: 検査・梱包
A25: 品目コード | C25: 品目名１ | F25: 在庫場所 | G25: 出庫数量 | I25: バッチ必要数
C26: 品目名２ | F26: 指図書備考
A28: J1JAZZA10818200 | C28: @8FL28130 L1820 | F28: V3J04 | G28: 50.1 | I28: 0.501
A29: *J1JAZZA10818200*
A30: J6DW0086 | C30: LED-A300（旧LED-A297） | F30: V3W04 | G30: 3 | I30: 0.03
A31: *J6DW0086* | C31: L300×W275×H166
A32: J6XX0050 | C32: (管理外)筋入ｸﾗﾌﾄ紙 | G32: 0.3 | I32: 0.003
A33: *J6XX0050* | C33: 300＊100
A34: J6XX0051 | C34: (管理外)LLDPE規格ｼｰﾄ0.02×950×100m | G34: 0.3 | I34: 0.003
A35: *J6XX0051* | C35: 0.02×950×100m
A38: 製品名 | E38: 備考、梱包方法等 | H38: 加工内容 | J38: 不良内訳
A39: =_xlfn.XLOOKUP(B3,[1]VFDB2!A:A,[1]VFDB2!B:B) -> 8FL281304 4810 L=297 | E39: =_xlfn.XLOOKUP(B3,[1]!テーブル5[品目コード],[1]!テーブル5[箱名]) -> LED-A300 | G39: =SUM(J48:J55) -> 3 | H39: 入庫日 | I39: {=IF(ISBLANK(INDEX(_xlfn._xlws.FILTER([1]加工記録２!$O$3:$P$500, [1]加工記録２!$T$3:$T$500=B5), 1)), "", INDEX(_xlfn._xlws.FILTER([1]加工記録２!$O$3:$P$500, [1]加工記録２!$T$3:$T$500=B5), 1))} -> 45818 | J39: 2
H40: 入庫数 | I40: {=IF(ISBLANK(INDEX(_xlfn._xlws.FILTER([1]加工記録２!$O$3:$P$500, [1]加工記録２!$T$3:$T$500=B5), 2)), "", INDEX(_xlfn._xlws.FILTER([1]加工記録２!$O$3:$P$500, [1]加工記録２!$T$3:$T$500=B5), 2))} -> 300
A41: 温度換算 | B41: =_xlfn.XLOOKUP(B3,[1]!テーブル5[品目コード],[1]!テーブル5[温度換算],,) -> 〇 | C41: 取数 | D41: =_xlfn.XLOOKUP(B3,[1]!テーブル5[品目コード],[1]!テーブル5[取数],,) -> 6 | E41: =_xlfn.XLOOKUP(B3,[1]!テーブル5[品目コード],[1]!テーブル5[備考１],,) -> 1箱目の梱包数 目視確認 以降、重量測定 | H41: 使用基材 | I41: {=IF(ISBLANK(INDEX(_xlfn._xlws.FILTER([1]加工記録２!$O$3:$P$500, [1]加工記録２!$T$3:$T$500=B5), 3)), "", INDEX(_xlfn._xlws.FILTER([1]加工記録２!$O$3:$P$500, [1]加工記録２!$T$3:$T$500=B5), 3))} -> 51
H42: 基材不良 | I42: {=IF(ISBLANK(INDEX(_xlfn._xlws.FILTER([1]加工記録２!$O$3:$P$500, [1]加工記録２!$T$3:$T$500=B5), 4)), "", INDEX(_xlfn._xlws.FILTER([1]加工記録２!$O$3:$P$500, [1]加工記録２!$T$3:$T$500=B5), 4))} -> 1
A43: L寸 | B43: =D3 -> 297 | C43: +公差 | D43: =_xlfn.XLOOKUP(B3,[1]!テーブル5[品目コード],[1]!テーブル5[上限公差],,) -> +0.5 | E43: =_xlfn.XLOOKUP(B3,[1]!テーブル5[品目コード],[1]!テーブル5[備考２],,) -> クラフト紙：592型 1/2 | H43: 製品不良 | I43: {=IF(ISBLANK(INDEX(_xlfn._xlws.FILTER([1]加工記録２!$O$3:$P$500, [1]加工記録２!$T$3:$T$500=B5), 5)), "", INDEX(_xlfn._xlws.FILTER([1]加工記録２!$O$3:$P$500, [1]加工記録２!$T$3:$T$500=B5), 5))} -> 2
H44: 端材使用 | I44: {=IF(ISBLANK(INDEX(_xlfn._xlws.FILTER([1]加工記録２!$O$3:$P$500, [1]加工記録２!$T$3:$T$500=B5), 6)), "", INDEX(_xlfn._xlws.FILTER([1]加工記録２!$O$3:$P$500, [1]加工記録２!$T$3:$T$500=B5), 6))}
A45: 切断寸法 | B45: =_xlfn.XLOOKUP(B3,[1]!テーブル5[品目コード],[1]!テーブル5[切断寸法],,) -> 換算表確認 | C45: -公差 | D45: =_xlfn.XLOOKUP(B3,[1]!テーブル5[品目コード],[1]!テーブル5[下限公差],,) -> －0.5 | E45: =_xlfn.XLOOKUP(B3,[1]!テーブル5[品目コード],[1]!テーブル5[梱包方法],,) -> ラベル１枚 長手無 鉢巻１回 | H45: 切断者 | I45: {=IF(ISBLANK(INDEX(_xlfn._xlws.FILTER([1]加工記録２!$O$3:$P$500, [1]加工記録２!$T$3:$T$500=B5), 7)), "", INDEX(_xlfn._xlws.FILTER([1]加工記録２!$O$3:$P$500, [1]加工記録２!$T$3:$T$500=B5), 7))} -> 水野
H46: 検査者 | I46: {=IF(ISBLANK(INDEX(_xlfn._xlws.FILTER([1]加工記録２!$O$3:$P$500, [1]加工記録２!$T$3:$T$500=B5), 8)), "", INDEX(_xlfn._xlws.FILTER([1]加工記録２!$O$3:$P$500, [1]加工記録２!$T$3:$T$500=B5), 8))} -> 高森 | J46: 2
A47: 作業日 | B47: 基材Lot | C47: 温度 | D47: 換算寸法 | E47: 計測値 | F47: 使用Lot | G47: B.加工数 | H47: C.基材換算 | I47: 加工Lot | J47: 箱数
A48: {=IF(ISBLANK(INDEX(_xlfn._xlws.FILTER([1]加工記録２!$D$3:$M$500, [1]加工記録２!$T$3:$T$500=B5), 1)), "", INDEX(_xlfn._xlws.FILTER([1]加工記録２!$D$3:$M$500, [1]加工記録２!$T$3:$T$500=B5), 1))} | F48: 25E27-09 | G48: 306 | H48: 51 | I48: 45818 | J48: 3
A49: {=IF(ISBLANK(INDEX(_xlfn._xlws.FILTER([1]加工記録２!$D$3:$M$500, [1]加工記録２!$T$3:$T$500=B5), 2)), "", INDEX(_xlfn._xlws.FILTER([1]加工記録２!$D$3:$M$500, [1]加工記録２!$T$3:$T$500=B5), 2))} -> 45817 | B49: 25E27-09 | C49: 26 | D49: 297.12 | E49: 297.22
A50: {=IF(ISBLANK(INDEX(_xlfn._xlws.FILTER([1]加工記録２!$D$3:$M$500, [1]加工記録２!$T$3:$T$500=B5), 3)), "", INDEX(_xlfn._xlws.FILTER([1]加工記録２!$D$3:$M$500, [1]加工記録２!$T$3:$T$500=B5), 3))} -> 45817 | B50: 25E27-09 | C50: 26 | D50: 297.12 | E50: 297.28
A51: {=IF(ISBLANK(INDEX(_xlfn._xlws.FILTER([1]加工記録２!$D$3:$M$500, [1]加工記録２!$T$3:$T$500=B5), 4)), "", INDEX(_xlfn._xlws.FILTER([1]加工記録２!$D$3:$M$500, [1]加工記録２!$T$3:$T$500=B5), 4))} -> 45818 | B51: 25E27-09 | C51: 22 | D51: 297.04 | E51: 297.28
A52: {=IF(ISBLANK(INDEX(_xlfn._xlws.FILTER([1]加工記録２!$D$3:$M$500, [1]加工記録２!$T$3:$T$500=B5), 5)), "", INDEX(_xlfn._xlws.FILTER([1]加工記録２!$D$3:$M$500, [1]加工記録２!$T$3:$T$500=B5), 5))} -> 45818 | B52: 25E27-09 | C52: 22 | D52: 297.04 | E52: 297.29
A53: {=IF(ISBLANK(INDEX(_xlfn._xlws.FILTER([1]加工記録２!$D$3:$M$500, [1]加工記録２!$T$3:$T$500=B5), 6)), "", INDEX(_xlfn._xlws.FILTER([1]加工記録２!$D$3:$M$500, [1]加工記録２!$T$3:$T$500=B5), 6))}
A54: {=IF(ISBLANK(INDEX(_xlfn._xlws.FILTER([1]加工記録２!$D$3:$M$500, [1]加工記録２!$T$3:$T$500=B5), 7)), "", INDEX(_xlfn._xlws.FILTER([1]加工記録２!$D$3:$M$500, [1]加工記録２!$T$3:$T$500=B5), 7))}
...
