Workbook
Name DB: #REF!

Sheet 帳票レイアウト Copy
B1: 検査梱包指示書
A3: 品目番号 | B3: J1ECZZB00105200 | C3: Ｌ寸 | D3: 520 | E3: 名称 | F3: L型ｱﾝｸﾞﾙP-VH-42D | I3: 上長 | J3: 係員
A5: 製造指図№ | B5: 000000000004267 | E5: 原料名 | F5: (J6VB075)
A7: 発注明細№ | B7: 000000000762880 | E7: 色 名 | F7: ｼﾛ
E8: 製品Grp | F8: J1EA
A9: 開始日 | B9: 45835 | E9: 入り数 | F9: 100
A10: 終了日 | B10: 45835 | E10: 梱包数 | F10: 4 | G10: 指示数量 | H10: 400
E11: 金 型 | F11: 4088
A12: *J1ECZZB00105200* | G12: 格納先 | H12: V3J03 | I12: 樹脂第3倉庫 (在庫)
A14: 指図書備考
A16: 工順 | B16: 製造場所 | C16: 製造場所名 | E16: 工程 | F16: 工程名 | I16: 作業時間
A18: 1 | B18: V3Z01 | C18: 黒部工業 | E18: V3P05 | F18: 切断
A19: 1 | B19: V3Z01 | C19: 黒部工業 | E19: V3P16 | F19: 検査・梱包
A25: 品目コード | C25: 品目名１ | F25: 在庫場所 | G25: 出庫数量 | I25: バッチ必要数
C26: 品目名２ | F26: 指図書備考
A28: J1ECZZA00116000 | C28: @L型ｱﾝｸﾞﾙ | F28: V3J01 | G28: 130 | I28: 1.3
A29: *J1ECZZA00116000* | C29: (J6VB075)
A30: J6DK0004 | C30: S-30 | F30: V3J03 | G30: 4 | I30: 0.04
A31: *J6DK0004*
A38: 製品名 | E38: 備考、梱包方法等 | H38: 加工内容 | J38: 不良内訳
A39: =_xlfn.XLOOKUP(B3,[1]VFDB2!A:A,[1]VFDB2!B:B) -> L型ｱﾝｸﾞﾙ P-VH-42D L=520 | E39: {=IFERROR(IF(ISBLANK(INDEX(_xlfn._xlws.FILTER([1]加工記録２!$C$3:$C$445, [1]加工記録２!$T$3:$T$445=B5), 6)), "", INDEX(_xlfn._xlws.FILTER([1]加工記録２!$C$3:$C$445, [1]加工記録２!$T$3:$T$445=B5), 6)),"")} -> S-30 | G39: {=IFERROR(IF(ISBLANK(INDEX(_xlfn._xlws.FILTER([1]加工記録２!$B$3:$B$445, [1]加工記録２!$T$3:$T$445=B5), 7)), "", INDEX(_xlfn._xlws.FILTER([1]加工記録２!$B$3:$B$445, [1]加工記録２!$T$3:$T$445=B5), 7)),"")} -> 4 | H39: 入庫日 | I39: {=IFERROR(IF(ISBLANK(INDEX(_xlfn._xlws.FILTER([1]加工記録２!$O$3:$P$445, [1]加工記録２!$T$3:$T$445=B5), 1)), "", INDEX(_xlfn._xlws.FILTER([1]加工記録２!$O$3:$P$445, [1]加工記録２!$T$3:$T$445=B5), 1)),"")} -> 45828
H40: 入庫数 | I40: {=IFERROR(IF(ISBLANK(INDEX(_xlfn._xlws.FILTER([1]加工記録２!$O$3:$P$445, [1]加工記録２!$T$3:$T$445=B5), 2)), "", INDEX(_xlfn._xlws.FILTER([1]加工記録２!$O$3:$P$445, [1]加工記録２!$T$3:$T$445=B5), 2)),"")} -> 400
A41: 温度換算 | B41: =_xlfn.XLOOKUP(B3,[1]!テーブル5[品目コード],[1]!テーブル5[温度換算],,) -> - | C41: 取数 | D41: 3 | E41: =_xlfn.XLOOKUP(B3,[1]!テーブル5[品目コード],[1]!テーブル5[備考１],,) -> 0 | H41: 使用基材 | I41: {=IFERROR(IF(ISBLANK(INDEX(_xlfn._xlws.FILTER([1]加工記録２!$O$3:$P$445, [1]加工記録２!$T$3:$T$445=B5), 3)), "", INDEX(_xlfn._xlws.FILTER([1]加工記録２!$O$3:$P$445, [1]加工記録２!$T$3:$T$445=B5), 3)),"")} -> 134
H42: 基材不良 | I42: {=IFERROR(IF(ISBLANK(INDEX(_xlfn._xlws.FILTER([1]加工記録２!$O$3:$P$445, [1]加工記録２!$T$3:$T$445=B5), 4)), "", INDEX(_xlfn._xlws.FILTER([1]加工記録２!$O$3:$P$445, [1]加工記録２!$T$3:$T$445=B5), 4)),"")} -> 0
A43: L寸 | B43: =D3 -> 520 | C43: +公差 | D43: =_xlfn.XLOOKUP(B3,[1]!テーブル5[品目コード],[1]!テーブル5[上限公差],,) -> 0 | E43: =_xlfn.XLOOKUP(B3,[1]!テーブル5[品目コード],[1]!テーブル5[備考２],,) -> ※使用基材、取数は依頼書にて確認 | H43: 製品不良 | I43: {=IFERROR(IF(ISBLANK(INDEX(_xlfn._xlws.FILTER([1]加工記録２!$O$3:$P$445, [1]加工記録２!$T$3:$T$445=B5), 5)), "", INDEX(_xlfn._xlws.FILTER([1]加工記録２!$O$3:$P$445, [1]加工記録２!$T$3:$T$445=B5), 5)),"")} -> 0
H44: 端材使用 | I44: {=IFERROR(IF(ISBLANK(INDEX(_xlfn._xlws.FILTER([1]加工記録２!$O$3:$P$445, [1]加工記録２!$T$3:$T$445=B5), 6)), "", INDEX(_xlfn._xlws.FILTER([1]加工記録２!$O$3:$P$445, [1]加工記録２!$T$3:$T$445=B5), 6)),"")}
A45: 切断寸法 | B45: =_xlfn.XLOOKUP(B3,[1]!テーブル5[品目コード],[1]!テーブル5[切断寸法],,) -> 519 | C45: -公差 | D45: =_xlfn.XLOOKUP(B3,[1]!テーブル5[品目コード],[1]!テーブル5[下限公差],,) -> -3 | E45: =_xlfn.XLOOKUP(B3,[1]!テーブル5[品目コード],[1]!テーブル5[梱包方法],,) -> ラベル２枚 長手有 鉢巻無 | H45: 切断者 | I45: {=IFERROR(IF(ISBLANK(INDEX(_xlfn._xlws.FILTER([1]加工記録２!$O$3:$P$445, [1]加工記録２!$T$3:$T$445=B5), 7)), "", INDEX(_xlfn._xlws.FILTER([1]加工記録２!$O$3:$P$445, [1]加工記録２!$T$3:$T$445=B5), 7)),"")} -> 富田・水野
H46: 検査者 | I46: {=IFERROR(IF(ISBLANK(INDEX(_xlfn._xlws.FILTER([1]加工記録２!$O$3:$P$445, [1]加工記録２!$T$3:$T$445=B5), 8)), "", INDEX(_xlfn._xlws.FILTER([1]加工記録２!$O$3:$P$445, [1]加工記録２!$T$3:$T$445=B5), 8)),"")} | J46: 0
A47: 作業日 | B47: 基材Lot | C47: 温度 | D47: 換算寸法 | E47: 計測値 | F47: 使用Lot | G47: 加工数 | H47: 基材換算 | I47: 加工Lot | J47: 箱数
A48: {=IFERROR(IF(ISBLANK(INDEX(_xlfn._xlws.FILTER([1]加工記録２!$D$3:$M$445, [1]加工記録２!$T$3:$T$445=B5), 1)), "", INDEX(_xlfn._xlws.FILTER([1]加工記録２!$D$3:$M$445, [1]加工記録２!$T$3:$T$445=B5), 1)),"")} | F48: 25F11B | G48: 402 | H48: 134 | I48: 45828 | J48: 4
A49: {=IFERROR(IF(ISBLANK(INDEX(_xlfn._xlws.FILTER([1]加工記録２!$D$3:$M$445, [1]加工記録２!$T$3:$T$445=B5), 2)), "", INDEX(_xlfn._xlws.FILTER([1]加工記録２!$D$3:$M$445, [1]加工記録２!$T$3:$T$445=B5), 2)),"")} -> 45828 | B49: 25F11B | D49: 520 | E49: 519.51
A50: {=IFERROR(IF(ISBLANK(INDEX(_xlfn._xlws.FILTER([1]加工記録２!$D$3:$M$445, [1]加工記録２!$T$3:$T$445=B5), 3)), "", INDEX(_xlfn._xlws.FILTER([1]加工記録２!$D$3:$M$445, [1]加工記録２!$T$3:$T$445=B5), 3)),"")} -> 45828 | B50: 25F11B | D50: 520 | E50: 519.61
A51: {=IFERROR(IF(ISBLANK(INDEX(_xlfn._xlws.FILTER([1]加工記録２!$D$3:$M$445, [1]加工記録２!$T$3:$T$445=B5), 4)), "", INDEX(_xlfn._xlws.FILTER([1]加工記録２!$D$3:$M$445, [1]加工記録２!$T$3:$T$445=B5), 4)),"")}
A52: {=IFERROR(IF(ISBLANK(INDEX(_xlfn._xlws.FILTER([1]加工記録２!$D$3:$M$445, [1]加工記録２!$T$3:$T$445=B5), 5)), "", INDEX(_xlfn._xlws.FILTER([1]加工記録２!$D$3:$M$445, [1]加工記録２!$T$3:$T$445=B5), 5)),"")}
A53: {=IFERROR(IF(ISBLANK(INDEX(_xlfn._xlws.FILTER([1]加工記録２!$D$3:$M$445, [1]加工記録２!$T$3:$T$445=B5), 6)), "", INDEX(_xlfn._xlws.FILTER([1]加工記録２!$D$3:$M$445, [1]加工記録２!$T$3:$T$445=B5), 6)),"")}
A54: {=IFERROR(IF(ISBLANK(INDEX(_xlfn._xlws.FILTER([1]加工記録２!$D$3:$M$445, [1]加工記録２!$T$3:$T$445=B5), 7)), "", INDEX(_xlfn._xlws.FILTER([1]加工記録２!$D$3:$M$445, [1]加工記録２!$T$3:$T$445=B5), 7)),"")}
A55: {=IFERROR(F(ISBLANK(INDEX(_xlfn._xlws.FILTER([1]加工記録２!$D$3:$M$445, [1]加工記録２!$T$3:$T$445=B5), 8)), "", INDEX(_xlfn._xlws.FILTER([1]加工記録２!$D$3:$M$445, [1]加工記録２!$T$3:$T$445=B5), 8)),"")}
B58: 検査梱包指示書
A60: 品目番号 | B60: J1ECZZB00105300 | C60: Ｌ寸 | D60: 530 | E60: 名称 | F60: L型ｱﾝｸﾞﾙP-VH-C | I60: 上長 | J60: 係員
A62: 製造指図№ | B62: 000000000004268 | E62: 原料名 | F62: (J6VB075)
...
