Workbook
Name DB: #REF!

Sheet 帳票レイアウト Copy
B1: 検査梱包指示書
A3: 品目番号 | B3: J1JAZZB10802970 | C3: Ｌ寸 | D3: 297 | E3: 名称 | F3: 8FL2813044810 | I3: 上長 | J3: 係員
A5: 製造指図№ | B5: 000000000007951 | E5: 原料名 | F5: (CASE 297MILK-W4)
A7: 発注明細№ | B7: 000000000794769 | E7: 色 名 | F7: J6VZ034
E8: 製品Grp | F8: J1ZB
A9: 開始日 | B9: 45958 | E9: 入り数 | F9: 100
A10: 終了日 | B10: 45958 | E10: 梱包数 | F10: 4 | G10: 指示数量 | H10: 400
E11: 金 型 | F11: 4350
A12: *J1JAZZB10802970* | G12: 格納先 | H12: V3J03 | I12: 樹脂第3倉庫 (在庫)
A14: 指図書備考
A16: 工順 | B16: 製造場所 | C16: 製造場所名 | E16: 工程 | F16: 工程名 | I16: 作業時間
A18: 1 | B18: V3Z01 | C18: 黒部工業 | E18: V3P05 | F18: 切断
A19: 1 | B19: V3Z01 | C19: 黒部工業 | E19: V3P16 | F19: 検査・梱包
A25: 品目コード | C25: 品目名１ | F25: 在庫場所 | G25: 出庫数量 | I25: バッチ必要数
C26: 品目名２ | F26: 指図書備考
A28: J1JAZZA10818200 | C28: @8FL28130 L1820 | F28: V3J04 | G28: 66.8 | I28: 0.668
A29: *J1JAZZA10818200*
A30: J6DW0086 | C30: LED-A300（旧LED-A297） | F30: V3W04 | G30: 4 | I30: 0.04
A31: *J6DW0086* | C31: L300×W275×H166
A32: J6XX0050 | C32: (管理外)筋入ｸﾗﾌﾄ紙 | G32: 0.4 | I32: 0.004
A33: *J6XX0050* | C33: 300＊100
A34: J6XX0051 | C34: (管理外)LLDPE規格ｼｰﾄ0.02×950×100m | G34: 0.4 | I34: 0.004
A35: *J6XX0051* | C35: 0.02×950×100m
A38: 製品名 | E38: 備考、梱包方法等 | G38: 使用数 | H38: 加工内容 | J38: 不良内訳
A39: =_xlfn.XLOOKUP(B3,[1]VFDB2!A:A,[1]VFDB2!B:B) -> 8FL281304 4810 L=297 | E39: {=IFERROR(IF(ISBLANK(INDEX(_xlfn._xlws.FILTER([1]加工記録２!$C$3:$C$999615, [1]加工記録２!$T$3:$T$999615=B5), 6)), "", INDEX(_xlfn._xlws.FILTER([1]加工記録２!$C$3:$C$999615, [1]加工記録２!$T$3:$T$999615=B5), 6)),"")} | G39: {=IFERROR(IF(ISBLANK(INDEX(_xlfn._xlws.FILTER([1]加工記録２!$C$3:$C$999615, [1]加工記録２!$T$3:$T$999615=B5), 7)), " ", INDEX(_xlfn._xlws.FILTER([1]加工記録２!$C$3:$C$999615, [1]加工記録２!$T$3:$T$999615=B5), 7))," ")} | H39: 入庫日 | I39: {=IFERROR(IF(ISBLANK(INDEX(_xlfn._xlws.FILTER([1]加工記録２!$O$3:$P$999678, [1]加工記録２!$T$3:$T$999678=$B$5), 1)), "", INDEX(_xlfn._xlws.FILTER([1]加工記録２!$O$3:$P$999678, [1]加工記録２!$T$3:$T$999678=$B$5), 1)),"")}
H40: 入庫数 | I40: {=IFERROR(IF(ISBLANK(INDEX(_xlfn._xlws.FILTER([1]加工記録２!$O$3:$P$999678, [1]加工記録２!$T$3:$T$999678=$B$5), 2)), "", INDEX(_xlfn._xlws.FILTER([1]加工記録２!$O$3:$P$999678, [1]加工記録２!$T$3:$T$999678=$B$5), 2)),"")}
A41: 温度換算 | B41: =_xlfn.XLOOKUP(B3,[1]VFDB2!A:A,[1]VFDB2!J:J) -> 〇 | C41: 取数 | D41: =_xlfn.XLOOKUP(B3,[1]VFDB2!A:A,[1]VFDB2!P:P) -> 6 | E41: =_xlfn.XLOOKUP(B3,[1]VFDB2!A:A,[1]VFDB2!V:V) -> 1箱目の梱包数 目視確認 以降、重量測定 | H41: 使用基材 | I41: {=IFERROR(IF(ISBLANK(INDEX(_xlfn._xlws.FILTER([1]加工記録２!$O$3:$P$999678,[1]加工記録２!$T$3:$T$999678=$B$5), 3)), "", INDEX(_xlfn._xlws.FILTER([1]加工記録２!$O$3:$P$999678, [1]加工記録２!$T$3:$T$999678=$B$5), 3)),"")}
H42: 基材不良 | I42: {=IFERROR(IF(ISBLANK(INDEX(_xlfn._xlws.FILTER([1]加工記録２!$O$3:$P$999678,[1]加工記録２!$T$3:$T$999678=$B$5), 4)), "", INDEX(_xlfn._xlws.FILTER([1]加工記録２!$O$3:$P$999678, [1]加工記録２!$T$3:$T$999678=$B$5), 4)),"")}
A43: L寸 | B43: =D3 -> 297 | C43: +公差 | D43: =_xlfn.XLOOKUP(B3,[1]VFDB2!A:A,[1]VFDB2!L:L) -> +0.5 | E43: =_xlfn.XLOOKUP(B3,[1]VFDB2!A:A,[1]VFDB2!W:W) -> クラフト紙：592型 1/2 | H43: 製品不良 | I43: {=IFERROR(IF(ISBLANK(INDEX(_xlfn._xlws.FILTER([1]加工記録２!$O$3:$P$999678,[1]加工記録２!$T$3:$T$999678=$B$5), 5)), "", INDEX(_xlfn._xlws.FILTER([1]加工記録２!$O$3:$P$999678, [1]加工記録２!$T$3:$T$999678=$B$5), 5)),"")}
H44: 端材使用 | I44: {=IFERROR(IF(ISBLANK(INDEX(_xlfn._xlws.FILTER([1]加工記録２!$O$3:$P$999678,[1]加工記録２!$T$3:$T$999678=$B$5), 6)), "", INDEX(_xlfn._xlws.FILTER([1]加工記録２!$O$3:$P$999678, [1]加工記録２!$T$3:$T$999678=$B$5), 6)),"")}
A45: 切断寸法 | B45: =_xlfn.XLOOKUP(B3,[1]VFDB2!A:A,[1]VFDB2!AC:AC) -> 換算表確認 | C45: -公差 | D45: =_xlfn.XLOOKUP(B3,[1]VFDB2!A:A,[1]VFDB2!K:K) -> －0.5 | E45: =_xlfn.XLOOKUP(B3,[1]VFDB2!A:A,[1]VFDB2!R:R) -> ラベル１枚 長手無 鉢巻１回 | H45: 切断者 | I45: {=IFERROR(IF(ISBLANK(INDEX(_xlfn._xlws.FILTER([1]加工記録２!$M$3:$M$999678, [1]加工記録２!$T$3:$T$999678=$B$5), 6)), "", INDEX(_xlfn._xlws.FILTER([1]加工記録２!$M$3:$M$999678, [1]加工記録２!$T$3:$T$999678=$B$5), 6)),"")} | J45: {=IFERROR(IF(ISBLANK(INDEX(_xlfn._xlws.FILTER([1]加工記録２!$P$3:$P$999678, [1]加工記録２!$T$3:$T$999678=B5), 7)), "", INDEX(_xlfn._xlws.FILTER([1]加工記録２!$P$3:$P$999678, [1]加工記録２!$T$3:$T$999678=B5), 7)),"")}
H46: 検査者 | I46: {=IFERROR(IF(ISBLANK(INDEX(_xlfn._xlws.FILTER([1]加工記録２!$M$3:$M$999678, [1]加工記録２!$T$3:$T$999678=$B$5), 7)), "", INDEX(_xlfn._xlws.FILTER([1]加工記録２!$M$3:$M$999678, [1]加工記録２!$T$3:$T$999678=$B$5), 7)),"")} | J46: =SUM(J39:J45) -> 0
A47: 作業日 | B47: 計測Lot | C47: 温度 | D47: 換算寸法 | E47: 計測値 | F47: 使用Lot | G47: 加工数 | H47: 基材換算 | I47: 加工Lot | J47: 箱数
A48: {=IFERROR(IF(ISBLANK(INDEX(_xlfn._xlws.FILTER([1]加工記録２!$D$3:$M$999678, [1]加工記録２!$T$3:$T$999678=$B$5), 1)), "", INDEX(_xlfn._xlws.FILTER([1]加工記録２!$D$3:$M$999678, [1]加工記録２!$T$3:$T$999678=$B$5), 1)),"")}
A49: {=IFERROR(IF(ISBLANK(INDEX(_xlfn._xlws.FILTER([1]加工記録２!$D$3:$M$999678, [1]加工記録２!$T$3:$T$999678=$B$5), 2)), "", INDEX(_xlfn._xlws.FILTER([1]加工記録２!$D$3:$M$999678, [1]加工記録２!$T$3:$T$999678=$B$5), 2)),"")}
A50: {=IFERROR(IF(ISBLANK(INDEX(_xlfn._xlws.FILTER([1]加工記録２!$D$3:$M$999678, [1]加工記録２!$T$3:$T$999678=$B$5), 3)), "", INDEX(_xlfn._xlws.FILTER([1]加工記録２!$D$3:$M$999678, [1]加工記録２!$T$3:$T$999678=$B$5), 3)),"")}
A51: {=IFERROR(IF(ISBLANK(INDEX(_xlfn._xlws.FILTER([1]加工記録２!$D$3:$M$999678, [1]加工記録２!$T$3:$T$999678=$B$5), 4)), "", INDEX(_xlfn._xlws.FILTER([1]加工記録２!$D$3:$M$999678, [1]加工記録２!$T$3:$T$999678=$B$5), 4)),"")}
A52: {=IFERROR(IF(ISBLANK(INDEX(_xlfn._xlws.FILTER([1]加工記録２!$D$3:$M$999678, [1]加工記録２!$T$3:$T$999678=$B$5), 5)), "", INDEX(_xlfn._xlws.FILTER([1]加工記録２!$D$3:$M$999678, [1]加工記録２!$T$3:$T$999678=$B$5), 5)),"")}
A53: {=IFERROR(IF(ISBLANK(INDEX(_xlfn._xlws.FILTER([1]加工記録２!$D$3:$K$999678, [1]加工記録２!$T$3:$T$999678=$B$5), 6)), "", INDEX(_xlfn._xlws.FILTER([1]加工記録２!$D$3:$K$999678, [1]加工記録２!$T$3:$T$999678=$B$5), 6)),"")}
A54: {=IFERROR(IF(ISBLANK(INDEX(_xlfn._xlws.FILTER([1]加工記録２!$D$3:$K$999678, [1]加工記録２!$T$3:$T$999678=$B$5), 7)), "", INDEX(_xlfn._xlws.FILTER([1]加工記録２!$D$3:$K$999678, [1]加工記録２!$T$3:$T$999678=$B$5), 7)),"")}
...
